[24/Jun/2014 12:23:12] ERROR [django.request:212] Internal Server Error: /favicon.ico
Traceback (most recent call last):
  File "/Users/osmundmaheswaran/development/sportsfronter-heroku-test/venv/lib/python2.7/site-packages/django/core/handlers/base.py", line 92, in get_response
    response = middleware_method(request)
  File "/Users/osmundmaheswaran/development/sportsfronter-heroku-test/venv/lib/python2.7/site-packages/django/middleware/common.py", line 69, in process_request
    if (not urlresolvers.is_valid_path(request.path_info, urlconf) and
  File "/Users/osmundmaheswaran/development/sportsfronter-heroku-test/venv/lib/python2.7/site-packages/django/core/urlresolvers.py", line 551, in is_valid_path
    resolve(path, urlconf)
  File "/Users/osmundmaheswaran/development/sportsfronter-heroku-test/venv/lib/python2.7/site-packages/django/core/urlresolvers.py", line 440, in resolve
    return get_resolver(urlconf).resolve(path)
  File "/Users/osmundmaheswaran/development/sportsfronter-heroku-test/venv/lib/python2.7/site-packages/django/core/urlresolvers.py", line 319, in resolve
    for pattern in self.url_patterns:
  File "/Users/osmundmaheswaran/development/sportsfronter-heroku-test/venv/lib/python2.7/site-packages/django/core/urlresolvers.py", line 347, in url_patterns
    patterns = getattr(self.urlconf_module, "urlpatterns", self.urlconf_module)
  File "/Users/osmundmaheswaran/development/sportsfronter-heroku-test/venv/lib/python2.7/site-packages/django/core/urlresolvers.py", line 342, in urlconf_module
    self._urlconf_module = import_module(self.urlconf_name)
  File "/Users/osmundmaheswaran/development/sportsfronter-heroku-test/venv/lib/python2.7/site-packages/django/utils/importlib.py", line 35, in import_module
    __import__(name)
  File "/Users/osmundmaheswaran/development/sportsfronter-heroku-test/webapp/sportsfronter/urls.py", line 12, in <module>
    site = Site.objects.get(pk=1)
  File "/Users/osmundmaheswaran/development/sportsfronter-heroku-test/venv/lib/python2.7/site-packages/django/db/models/manager.py", line 143, in get
    return self.get_query_set().get(*args, **kwargs)
  File "/Users/osmundmaheswaran/development/sportsfronter-heroku-test/venv/lib/python2.7/site-packages/django/db/models/query.py", line 382, in get
    num = len(clone)
  File "/Users/osmundmaheswaran/development/sportsfronter-heroku-test/venv/lib/python2.7/site-packages/django/db/models/query.py", line 90, in __len__
    self._result_cache = list(self.iterator())
  File "/Users/osmundmaheswaran/development/sportsfronter-heroku-test/venv/lib/python2.7/site-packages/django/db/models/query.py", line 301, in iterator
    for row in compiler.results_iter():
  File "/Users/osmundmaheswaran/development/sportsfronter-heroku-test/venv/lib/python2.7/site-packages/django/db/models/sql/compiler.py", line 775, in results_iter
    for rows in self.execute_sql(MULTI):
  File "/Users/osmundmaheswaran/development/sportsfronter-heroku-test/venv/lib/python2.7/site-packages/django/db/models/sql/compiler.py", line 839, in execute_sql
    cursor = self.connection.cursor()
  File "/Users/osmundmaheswaran/development/sportsfronter-heroku-test/venv/lib/python2.7/site-packages/django/db/backends/__init__.py", line 324, in cursor
    cursor = self.make_debug_cursor(self._cursor())
  File "/Users/osmundmaheswaran/development/sportsfronter-heroku-test/venv/lib/python2.7/site-packages/django/db/backends/postgresql_psycopg2/base.py", line 182, in _cursor
    self.connection = Database.connect(**conn_params)
  File "/Users/osmundmaheswaran/development/sportsfronter-heroku-test/venv/lib/python2.7/site-packages/psycopg2/__init__.py", line 164, in connect
    conn = _connect(dsn, connection_factory=connection_factory, async=async)
OperationalError: could not connect to server: Connection refused
	Is the server running on host "localhost" (::1) and accepting
	TCP/IP connections on port 5432?
could not connect to server: Connection refused
	Is the server running on host "localhost" (fe80::1) and accepting
	TCP/IP connections on port 5432?
could not connect to server: Connection refused
	Is the server running on host "localhost" (127.0.0.1) and accepting
	TCP/IP connections on port 5432?

