[26/Jun/2014 08:30:05] ERROR [django.request:212] Internal Server Error: /auth/login
Traceback (most recent call last):
  File "/Users/osmundmaheswaran/development/sportsfronter-heroku-test/venv/lib/python2.7/site-packages/django/core/handlers/base.py", line 115, in get_response
    response = callback(request, *callback_args, **callback_kwargs)
  File "/Users/osmundmaheswaran/development/sportsfronter-heroku-test/venv/lib/python2.7/site-packages/django/views/decorators/csrf.py", line 77, in wrapped_view
    return view_func(*args, **kwargs)
  File "/Users/osmundmaheswaran/development/sportsfronter-heroku-test/webapp/auth/views.py", line 206, in _login
    token = Token.objects.create(user=user).pk
  File "/Users/osmundmaheswaran/development/sportsfronter-heroku-test/venv/lib/python2.7/site-packages/django/db/models/manager.py", line 149, in create
    return self.get_query_set().create(**kwargs)
  File "/Users/osmundmaheswaran/development/sportsfronter-heroku-test/venv/lib/python2.7/site-packages/django/db/models/query.py", line 402, in create
    obj.save(force_insert=True, using=self.db)
  File "/Users/osmundmaheswaran/development/sportsfronter-heroku-test/venv/lib/python2.7/site-packages/rest_framework/authtoken/models.py", line 28, in save
    return super(Token, self).save(*args, **kwargs)
  File "/Users/osmundmaheswaran/development/sportsfronter-heroku-test/venv/lib/python2.7/site-packages/django/db/models/base.py", line 546, in save
    force_update=force_update, update_fields=update_fields)
  File "/Users/osmundmaheswaran/development/sportsfronter-heroku-test/venv/lib/python2.7/site-packages/django/db/models/base.py", line 650, in save_base
    result = manager._insert([self], fields=fields, return_id=update_pk, using=using, raw=raw)
  File "/Users/osmundmaheswaran/development/sportsfronter-heroku-test/venv/lib/python2.7/site-packages/django/db/models/manager.py", line 215, in _insert
    return insert_query(self.model, objs, fields, **kwargs)
  File "/Users/osmundmaheswaran/development/sportsfronter-heroku-test/venv/lib/python2.7/site-packages/django/db/models/query.py", line 1661, in insert_query
    return query.get_compiler(using=using).execute_sql(return_id)
  File "/Users/osmundmaheswaran/development/sportsfronter-heroku-test/venv/lib/python2.7/site-packages/django/db/models/sql/compiler.py", line 937, in execute_sql
    cursor.execute(sql, params)
  File "/Users/osmundmaheswaran/development/sportsfronter-heroku-test/venv/lib/python2.7/site-packages/django/db/backends/util.py", line 41, in execute
    return self.cursor.execute(sql, params)
  File "/Users/osmundmaheswaran/development/sportsfronter-heroku-test/venv/lib/python2.7/site-packages/django/db/backends/postgresql_psycopg2/base.py", line 58, in execute
    six.reraise(utils.DatabaseError, utils.DatabaseError(*tuple(e.args)), sys.exc_info()[2])
  File "/Users/osmundmaheswaran/development/sportsfronter-heroku-test/venv/lib/python2.7/site-packages/django/db/backends/postgresql_psycopg2/base.py", line 54, in execute
    return self.cursor.execute(query, args)
DatabaseError: current transaction is aborted, commands ignored until end of transaction block

[26/Jun/2014 08:30:40] INFO [sportsfronter.auth.views:192] data: {"username": "gunicorn@example.com", "password": "random"}
[26/Jun/2014 08:30:40] ERROR [django.request:212] Internal Server Error: /auth/login
Traceback (most recent call last):
  File "/Users/osmundmaheswaran/development/sportsfronter-heroku-test/venv/lib/python2.7/site-packages/django/core/handlers/base.py", line 115, in get_response
    response = callback(request, *callback_args, **callback_kwargs)
  File "/Users/osmundmaheswaran/development/sportsfronter-heroku-test/venv/lib/python2.7/site-packages/django/views/decorators/csrf.py", line 77, in wrapped_view
    return view_func(*args, **kwargs)
  File "/Users/osmundmaheswaran/development/sportsfronter-heroku-test/webapp/auth/views.py", line 206, in _login
    token = Token.objects.create(user=user).pk
  File "/Users/osmundmaheswaran/development/sportsfronter-heroku-test/venv/lib/python2.7/site-packages/django/db/models/manager.py", line 149, in create
    return self.get_query_set().create(**kwargs)
  File "/Users/osmundmaheswaran/development/sportsfronter-heroku-test/venv/lib/python2.7/site-packages/django/db/models/query.py", line 402, in create
    obj.save(force_insert=True, using=self.db)
  File "/Users/osmundmaheswaran/development/sportsfronter-heroku-test/venv/lib/python2.7/site-packages/rest_framework/authtoken/models.py", line 28, in save
    return super(Token, self).save(*args, **kwargs)
  File "/Users/osmundmaheswaran/development/sportsfronter-heroku-test/venv/lib/python2.7/site-packages/django/db/models/base.py", line 546, in save
    force_update=force_update, update_fields=update_fields)
  File "/Users/osmundmaheswaran/development/sportsfronter-heroku-test/venv/lib/python2.7/site-packages/django/db/models/base.py", line 650, in save_base
    result = manager._insert([self], fields=fields, return_id=update_pk, using=using, raw=raw)
  File "/Users/osmundmaheswaran/development/sportsfronter-heroku-test/venv/lib/python2.7/site-packages/django/db/models/manager.py", line 215, in _insert
    return insert_query(self.model, objs, fields, **kwargs)
  File "/Users/osmundmaheswaran/development/sportsfronter-heroku-test/venv/lib/python2.7/site-packages/django/db/models/query.py", line 1661, in insert_query
    return query.get_compiler(using=using).execute_sql(return_id)
  File "/Users/osmundmaheswaran/development/sportsfronter-heroku-test/venv/lib/python2.7/site-packages/django/db/models/sql/compiler.py", line 937, in execute_sql
    cursor.execute(sql, params)
  File "/Users/osmundmaheswaran/development/sportsfronter-heroku-test/venv/lib/python2.7/site-packages/django/db/backends/util.py", line 41, in execute
    return self.cursor.execute(sql, params)
  File "/Users/osmundmaheswaran/development/sportsfronter-heroku-test/venv/lib/python2.7/site-packages/django/db/backends/postgresql_psycopg2/base.py", line 58, in execute
    six.reraise(utils.DatabaseError, utils.DatabaseError(*tuple(e.args)), sys.exc_info()[2])
  File "/Users/osmundmaheswaran/development/sportsfronter-heroku-test/venv/lib/python2.7/site-packages/django/db/backends/postgresql_psycopg2/base.py", line 54, in execute
    return self.cursor.execute(query, args)
DatabaseError: current transaction is aborted, commands ignored until end of transaction block

[26/Jun/2014 08:38:59] WARNING [django.request:146] Not Found: /favicon.ico
[26/Jun/2014 08:38:59] WARNING [django.request:146] Not Found: /static/webapp/js/angular.min.js.map
[26/Jun/2014 08:38:59] WARNING [django.request:146] Not Found: /static/webapp/js/jquery.min.map
[26/Jun/2014 08:38:59] WARNING [django.request:146] Not Found: /static/webapp/js/angular-cookies.min.js.map
[26/Jun/2014 08:38:59] WARNING [django.request:146] Not Found: /static/webapp/js/angular-route.min.js.map
[26/Jun/2014 08:38:59] WARNING [django.request:146] Not Found: /static/webapp/js/angular-touch.min.js.map
[26/Jun/2014 08:39:07] INFO [sportsfronter.auth.views:192] data: {"username": "gunicorn@example.com", "password": "random"}
[26/Jun/2014 08:39:07] ERROR [django.request:212] Internal Server Error: /auth/login
Traceback (most recent call last):
  File "/Users/osmundmaheswaran/development/sportsfronter-heroku-test/venv/lib/python2.7/site-packages/django/core/handlers/base.py", line 115, in get_response
    response = callback(request, *callback_args, **callback_kwargs)
  File "/Users/osmundmaheswaran/development/sportsfronter-heroku-test/venv/lib/python2.7/site-packages/django/views/decorators/csrf.py", line 77, in wrapped_view
    return view_func(*args, **kwargs)
  File "/Users/osmundmaheswaran/development/sportsfronter-heroku-test/webapp/auth/views.py", line 206, in _login
    token = Token.objects.create(user=user).pk
  File "/Users/osmundmaheswaran/development/sportsfronter-heroku-test/venv/lib/python2.7/site-packages/django/db/models/manager.py", line 149, in create
    return self.get_query_set().create(**kwargs)
  File "/Users/osmundmaheswaran/development/sportsfronter-heroku-test/venv/lib/python2.7/site-packages/django/db/models/query.py", line 402, in create
    obj.save(force_insert=True, using=self.db)
  File "/Users/osmundmaheswaran/development/sportsfronter-heroku-test/venv/lib/python2.7/site-packages/rest_framework/authtoken/models.py", line 28, in save
    return super(Token, self).save(*args, **kwargs)
  File "/Users/osmundmaheswaran/development/sportsfronter-heroku-test/venv/lib/python2.7/site-packages/django/db/models/base.py", line 546, in save
    force_update=force_update, update_fields=update_fields)
  File "/Users/osmundmaheswaran/development/sportsfronter-heroku-test/venv/lib/python2.7/site-packages/django/db/models/base.py", line 650, in save_base
    result = manager._insert([self], fields=fields, return_id=update_pk, using=using, raw=raw)
  File "/Users/osmundmaheswaran/development/sportsfronter-heroku-test/venv/lib/python2.7/site-packages/django/db/models/manager.py", line 215, in _insert
    return insert_query(self.model, objs, fields, **kwargs)
  File "/Users/osmundmaheswaran/development/sportsfronter-heroku-test/venv/lib/python2.7/site-packages/django/db/models/query.py", line 1661, in insert_query
    return query.get_compiler(using=using).execute_sql(return_id)
  File "/Users/osmundmaheswaran/development/sportsfronter-heroku-test/venv/lib/python2.7/site-packages/django/db/models/sql/compiler.py", line 937, in execute_sql
    cursor.execute(sql, params)
  File "/Users/osmundmaheswaran/development/sportsfronter-heroku-test/venv/lib/python2.7/site-packages/django/db/backends/util.py", line 41, in execute
    return self.cursor.execute(sql, params)
  File "/Users/osmundmaheswaran/development/sportsfronter-heroku-test/venv/lib/python2.7/site-packages/django/db/backends/postgresql_psycopg2/base.py", line 58, in execute
    six.reraise(utils.DatabaseError, utils.DatabaseError(*tuple(e.args)), sys.exc_info()[2])
  File "/Users/osmundmaheswaran/development/sportsfronter-heroku-test/venv/lib/python2.7/site-packages/django/db/backends/postgresql_psycopg2/base.py", line 54, in execute
    return self.cursor.execute(query, args)
DatabaseError: current transaction is aborted, commands ignored until end of transaction block

[26/Jun/2014 08:39:10] ERROR [django.request:212] Internal Server Error: /auth/login
Traceback (most recent call last):
  File "/Users/osmundmaheswaran/development/sportsfronter-heroku-test/venv/lib/python2.7/site-packages/django/core/handlers/base.py", line 115, in get_response
    response = callback(request, *callback_args, **callback_kwargs)
  File "/Users/osmundmaheswaran/development/sportsfronter-heroku-test/venv/lib/python2.7/site-packages/django/views/decorators/csrf.py", line 77, in wrapped_view
    return view_func(*args, **kwargs)
  File "/Users/osmundmaheswaran/development/sportsfronter-heroku-test/webapp/auth/views.py", line 182, in _login
    data = json.loads(request.body)
  File "/usr/local/Cellar/python/2.7.5/Frameworks/Python.framework/Versions/2.7/lib/python2.7/json/__init__.py", line 338, in loads
    return _default_decoder.decode(s)
  File "/usr/local/Cellar/python/2.7.5/Frameworks/Python.framework/Versions/2.7/lib/python2.7/json/decoder.py", line 365, in decode
    obj, end = self.raw_decode(s, idx=_w(s, 0).end())
  File "/usr/local/Cellar/python/2.7.5/Frameworks/Python.framework/Versions/2.7/lib/python2.7/json/decoder.py", line 383, in raw_decode
    raise ValueError("No JSON object could be decoded")
ValueError: No JSON object could be decoded
[26/Jun/2014 09:14:02] WARNING [django.request:146] Not Found: /static/webapp/js/angular.min.js.map
[26/Jun/2014 09:14:02] WARNING [django.request:146] Not Found: /static/webapp/js/jquery.min.map
[26/Jun/2014 09:14:02] WARNING [django.request:146] Not Found: /static/webapp/js/angular-cookies.min.js.map
[26/Jun/2014 09:14:02] WARNING [django.request:146] Not Found: /static/webapp/js/angular-route.min.js.map
[26/Jun/2014 09:14:02] WARNING [django.request:146] Not Found: /static/webapp/js/angular-touch.min.js.map
[26/Jun/2014 09:15:00] INFO [sportsfronter.auth.views:251] data: {"username": "lol@lol.com", "firstName": "Lol", "lastName": "Lol", "userRoles": {"player": false, "manager": false, "guardian": false}, "password": "random", "newUser": true}
[26/Jun/2014 09:15:00] ERROR [django.request:212] Internal Server Error: /auth/register
Traceback (most recent call last):
  File "/Users/osmundmaheswaran/development/sportsfronter-heroku-test/venv/lib/python2.7/site-packages/django/core/handlers/base.py", line 115, in get_response
    response = callback(request, *callback_args, **callback_kwargs)
  File "/Users/osmundmaheswaran/development/sportsfronter-heroku-test/venv/lib/python2.7/site-packages/django/views/decorators/csrf.py", line 77, in wrapped_view
    return view_func(*args, **kwargs)
  File "/Users/osmundmaheswaran/development/sportsfronter-heroku-test/webapp/auth/views.py", line 295, in register
    Token.objects.create(user=person).save()
  File "/Users/osmundmaheswaran/development/sportsfronter-heroku-test/venv/lib/python2.7/site-packages/django/db/models/manager.py", line 149, in create
    return self.get_query_set().create(**kwargs)
  File "/Users/osmundmaheswaran/development/sportsfronter-heroku-test/venv/lib/python2.7/site-packages/django/db/models/query.py", line 402, in create
    obj.save(force_insert=True, using=self.db)
  File "/Users/osmundmaheswaran/development/sportsfronter-heroku-test/venv/lib/python2.7/site-packages/rest_framework/authtoken/models.py", line 28, in save
    return super(Token, self).save(*args, **kwargs)
  File "/Users/osmundmaheswaran/development/sportsfronter-heroku-test/venv/lib/python2.7/site-packages/django/db/models/base.py", line 546, in save
    force_update=force_update, update_fields=update_fields)
  File "/Users/osmundmaheswaran/development/sportsfronter-heroku-test/venv/lib/python2.7/site-packages/django/db/models/base.py", line 650, in save_base
    result = manager._insert([self], fields=fields, return_id=update_pk, using=using, raw=raw)
  File "/Users/osmundmaheswaran/development/sportsfronter-heroku-test/venv/lib/python2.7/site-packages/django/db/models/manager.py", line 215, in _insert
    return insert_query(self.model, objs, fields, **kwargs)
  File "/Users/osmundmaheswaran/development/sportsfronter-heroku-test/venv/lib/python2.7/site-packages/django/db/models/query.py", line 1661, in insert_query
    return query.get_compiler(using=using).execute_sql(return_id)
  File "/Users/osmundmaheswaran/development/sportsfronter-heroku-test/venv/lib/python2.7/site-packages/django/db/models/sql/compiler.py", line 937, in execute_sql
    cursor.execute(sql, params)
  File "/Users/osmundmaheswaran/development/sportsfronter-heroku-test/venv/lib/python2.7/site-packages/django/db/backends/util.py", line 41, in execute
    return self.cursor.execute(sql, params)
  File "/Users/osmundmaheswaran/development/sportsfronter-heroku-test/venv/lib/python2.7/site-packages/django/db/backends/postgresql_psycopg2/base.py", line 58, in execute
    six.reraise(utils.DatabaseError, utils.DatabaseError(*tuple(e.args)), sys.exc_info()[2])
  File "/Users/osmundmaheswaran/development/sportsfronter-heroku-test/venv/lib/python2.7/site-packages/django/db/backends/postgresql_psycopg2/base.py", line 54, in execute
    return self.cursor.execute(query, args)
DatabaseError: relation "authtoken_token" does not exist
LINE 1: INSERT INTO "authtoken_token" ("key", "user_id", "created") ...
                    ^

[26/Jun/2014 09:15:47] INFO [sportsfronter.auth.views:251] data: {"username": "lol@lol.com", "firstName": "Lol", "lastName": "Lol", "userRoles": {"player": false, "manager": false, "guardian": false}, "password": "random", "newUser": true}
[26/Jun/2014 09:15:47] INFO [sportsfronter.auth.views:192] data: {"username": "lol@lol.com", "password": "random"}
[26/Jun/2014 09:15:48] INFO [sportsfronter.auth.views:227] User lol@lol.com logged in.
[26/Jun/2014 09:16:03] INFO [sportsfronter.auth.views:192] data: {"username": "lol@lol.com", "password": "random"}
[26/Jun/2014 09:16:03] INFO [sportsfronter.auth.views:227] User lol@lol.com logged in.
