[24/Jun/2014 12:23:12] ERROR [django.request:212] Internal Server Error: /favicon.ico
Traceback (most recent call last):
  File "/Users/osmundmaheswaran/development/sportsfronter-heroku-test/venv/lib/python2.7/site-packages/django/core/handlers/base.py", line 92, in get_response
    response = middleware_method(request)
  File "/Users/osmundmaheswaran/development/sportsfronter-heroku-test/venv/lib/python2.7/site-packages/django/middleware/common.py", line 69, in process_request
    if (not urlresolvers.is_valid_path(request.path_info, urlconf) and
  File "/Users/osmundmaheswaran/development/sportsfronter-heroku-test/venv/lib/python2.7/site-packages/django/core/urlresolvers.py", line 551, in is_valid_path
    resolve(path, urlconf)
  File "/Users/osmundmaheswaran/development/sportsfronter-heroku-test/venv/lib/python2.7/site-packages/django/core/urlresolvers.py", line 440, in resolve
    return get_resolver(urlconf).resolve(path)
  File "/Users/osmundmaheswaran/development/sportsfronter-heroku-test/venv/lib/python2.7/site-packages/django/core/urlresolvers.py", line 319, in resolve
    for pattern in self.url_patterns:
  File "/Users/osmundmaheswaran/development/sportsfronter-heroku-test/venv/lib/python2.7/site-packages/django/core/urlresolvers.py", line 347, in url_patterns
    patterns = getattr(self.urlconf_module, "urlpatterns", self.urlconf_module)
  File "/Users/osmundmaheswaran/development/sportsfronter-heroku-test/venv/lib/python2.7/site-packages/django/core/urlresolvers.py", line 342, in urlconf_module
    self._urlconf_module = import_module(self.urlconf_name)
  File "/Users/osmundmaheswaran/development/sportsfronter-heroku-test/venv/lib/python2.7/site-packages/django/utils/importlib.py", line 35, in import_module
    __import__(name)
  File "/Users/osmundmaheswaran/development/sportsfronter-heroku-test/webapp/sportsfronter/urls.py", line 12, in <module>
    site = Site.objects.get(pk=1)
  File "/Users/osmundmaheswaran/development/sportsfronter-heroku-test/venv/lib/python2.7/site-packages/django/db/models/manager.py", line 143, in get
    return self.get_query_set().get(*args, **kwargs)
  File "/Users/osmundmaheswaran/development/sportsfronter-heroku-test/venv/lib/python2.7/site-packages/django/db/models/query.py", line 382, in get
    num = len(clone)
  File "/Users/osmundmaheswaran/development/sportsfronter-heroku-test/venv/lib/python2.7/site-packages/django/db/models/query.py", line 90, in __len__
    self._result_cache = list(self.iterator())
  File "/Users/osmundmaheswaran/development/sportsfronter-heroku-test/venv/lib/python2.7/site-packages/django/db/models/query.py", line 301, in iterator
    for row in compiler.results_iter():
  File "/Users/osmundmaheswaran/development/sportsfronter-heroku-test/venv/lib/python2.7/site-packages/django/db/models/sql/compiler.py", line 775, in results_iter
    for rows in self.execute_sql(MULTI):
  File "/Users/osmundmaheswaran/development/sportsfronter-heroku-test/venv/lib/python2.7/site-packages/django/db/models/sql/compiler.py", line 839, in execute_sql
    cursor = self.connection.cursor()
  File "/Users/osmundmaheswaran/development/sportsfronter-heroku-test/venv/lib/python2.7/site-packages/django/db/backends/__init__.py", line 324, in cursor
    cursor = self.make_debug_cursor(self._cursor())
  File "/Users/osmundmaheswaran/development/sportsfronter-heroku-test/venv/lib/python2.7/site-packages/django/db/backends/postgresql_psycopg2/base.py", line 182, in _cursor
    self.connection = Database.connect(**conn_params)
  File "/Users/osmundmaheswaran/development/sportsfronter-heroku-test/venv/lib/python2.7/site-packages/psycopg2/__init__.py", line 164, in connect
    conn = _connect(dsn, connection_factory=connection_factory, async=async)
OperationalError: could not connect to server: Connection refused
	Is the server running on host "localhost" (::1) and accepting
	TCP/IP connections on port 5432?
could not connect to server: Connection refused
	Is the server running on host "localhost" (fe80::1) and accepting
	TCP/IP connections on port 5432?
could not connect to server: Connection refused
	Is the server running on host "localhost" (127.0.0.1) and accepting
	TCP/IP connections on port 5432?

[24/Jun/2014 13:59:09] ERROR [django.request:212] Internal Server Error: /
Traceback (most recent call last):
  File "/Users/osmundmaheswaran/development/sportsfronter-heroku-test/venv/lib/python2.7/site-packages/django/core/handlers/base.py", line 103, in get_response
    resolver_match = resolver.resolve(request.path_info)
  File "/Users/osmundmaheswaran/development/sportsfronter-heroku-test/venv/lib/python2.7/site-packages/django/core/urlresolvers.py", line 319, in resolve
    for pattern in self.url_patterns:
  File "/Users/osmundmaheswaran/development/sportsfronter-heroku-test/venv/lib/python2.7/site-packages/django/core/urlresolvers.py", line 347, in url_patterns
    patterns = getattr(self.urlconf_module, "urlpatterns", self.urlconf_module)
  File "/Users/osmundmaheswaran/development/sportsfronter-heroku-test/venv/lib/python2.7/site-packages/django/core/urlresolvers.py", line 342, in urlconf_module
    self._urlconf_module = import_module(self.urlconf_name)
  File "/Users/osmundmaheswaran/development/sportsfronter-heroku-test/venv/lib/python2.7/site-packages/django/utils/importlib.py", line 35, in import_module
    __import__(name)
  File "/Users/osmundmaheswaran/development/sportsfronter-heroku-test/webapp/sportsfronter/urls.py", line 12, in <module>
    site = Site.objects.get(pk=1)
  File "/Users/osmundmaheswaran/development/sportsfronter-heroku-test/venv/lib/python2.7/site-packages/django/db/models/manager.py", line 143, in get
    return self.get_query_set().get(*args, **kwargs)
  File "/Users/osmundmaheswaran/development/sportsfronter-heroku-test/venv/lib/python2.7/site-packages/django/db/models/query.py", line 382, in get
    num = len(clone)
  File "/Users/osmundmaheswaran/development/sportsfronter-heroku-test/venv/lib/python2.7/site-packages/django/db/models/query.py", line 90, in __len__
    self._result_cache = list(self.iterator())
  File "/Users/osmundmaheswaran/development/sportsfronter-heroku-test/venv/lib/python2.7/site-packages/django/db/models/query.py", line 301, in iterator
    for row in compiler.results_iter():
  File "/Users/osmundmaheswaran/development/sportsfronter-heroku-test/venv/lib/python2.7/site-packages/django/db/models/sql/compiler.py", line 775, in results_iter
    for rows in self.execute_sql(MULTI):
  File "/Users/osmundmaheswaran/development/sportsfronter-heroku-test/venv/lib/python2.7/site-packages/django/db/models/sql/compiler.py", line 839, in execute_sql
    cursor = self.connection.cursor()
  File "/Users/osmundmaheswaran/development/sportsfronter-heroku-test/venv/lib/python2.7/site-packages/django/db/backends/__init__.py", line 324, in cursor
    cursor = self.make_debug_cursor(self._cursor())
  File "/Users/osmundmaheswaran/development/sportsfronter-heroku-test/venv/lib/python2.7/site-packages/django/db/backends/postgresql_psycopg2/base.py", line 182, in _cursor
    self.connection = Database.connect(**conn_params)
  File "/Users/osmundmaheswaran/development/sportsfronter-heroku-test/venv/lib/python2.7/site-packages/psycopg2/__init__.py", line 164, in connect
    conn = _connect(dsn, connection_factory=connection_factory, async=async)
OperationalError: FATAL:  role "sportsfronter" does not exist

[24/Jun/2014 13:59:09] ERROR [django.request:212] Internal Server Error: /favicon.ico
Traceback (most recent call last):
  File "/Users/osmundmaheswaran/development/sportsfronter-heroku-test/venv/lib/python2.7/site-packages/django/core/handlers/base.py", line 92, in get_response
    response = middleware_method(request)
  File "/Users/osmundmaheswaran/development/sportsfronter-heroku-test/venv/lib/python2.7/site-packages/django/middleware/common.py", line 69, in process_request
    if (not urlresolvers.is_valid_path(request.path_info, urlconf) and
  File "/Users/osmundmaheswaran/development/sportsfronter-heroku-test/venv/lib/python2.7/site-packages/django/core/urlresolvers.py", line 551, in is_valid_path
    resolve(path, urlconf)
  File "/Users/osmundmaheswaran/development/sportsfronter-heroku-test/venv/lib/python2.7/site-packages/django/core/urlresolvers.py", line 440, in resolve
    return get_resolver(urlconf).resolve(path)
  File "/Users/osmundmaheswaran/development/sportsfronter-heroku-test/venv/lib/python2.7/site-packages/django/core/urlresolvers.py", line 319, in resolve
    for pattern in self.url_patterns:
  File "/Users/osmundmaheswaran/development/sportsfronter-heroku-test/venv/lib/python2.7/site-packages/django/core/urlresolvers.py", line 347, in url_patterns
    patterns = getattr(self.urlconf_module, "urlpatterns", self.urlconf_module)
  File "/Users/osmundmaheswaran/development/sportsfronter-heroku-test/venv/lib/python2.7/site-packages/django/core/urlresolvers.py", line 342, in urlconf_module
    self._urlconf_module = import_module(self.urlconf_name)
  File "/Users/osmundmaheswaran/development/sportsfronter-heroku-test/venv/lib/python2.7/site-packages/django/utils/importlib.py", line 35, in import_module
    __import__(name)
  File "/Users/osmundmaheswaran/development/sportsfronter-heroku-test/webapp/sportsfronter/urls.py", line 12, in <module>
    site = Site.objects.get(pk=1)
  File "/Users/osmundmaheswaran/development/sportsfronter-heroku-test/venv/lib/python2.7/site-packages/django/db/models/manager.py", line 143, in get
    return self.get_query_set().get(*args, **kwargs)
  File "/Users/osmundmaheswaran/development/sportsfronter-heroku-test/venv/lib/python2.7/site-packages/django/db/models/query.py", line 382, in get
    num = len(clone)
  File "/Users/osmundmaheswaran/development/sportsfronter-heroku-test/venv/lib/python2.7/site-packages/django/db/models/query.py", line 90, in __len__
    self._result_cache = list(self.iterator())
  File "/Users/osmundmaheswaran/development/sportsfronter-heroku-test/venv/lib/python2.7/site-packages/django/db/models/query.py", line 301, in iterator
    for row in compiler.results_iter():
  File "/Users/osmundmaheswaran/development/sportsfronter-heroku-test/venv/lib/python2.7/site-packages/django/db/models/sql/compiler.py", line 775, in results_iter
    for rows in self.execute_sql(MULTI):
  File "/Users/osmundmaheswaran/development/sportsfronter-heroku-test/venv/lib/python2.7/site-packages/django/db/models/sql/compiler.py", line 839, in execute_sql
    cursor = self.connection.cursor()
  File "/Users/osmundmaheswaran/development/sportsfronter-heroku-test/venv/lib/python2.7/site-packages/django/db/backends/__init__.py", line 324, in cursor
    cursor = self.make_debug_cursor(self._cursor())
  File "/Users/osmundmaheswaran/development/sportsfronter-heroku-test/venv/lib/python2.7/site-packages/django/db/backends/postgresql_psycopg2/base.py", line 182, in _cursor
    self.connection = Database.connect(**conn_params)
  File "/Users/osmundmaheswaran/development/sportsfronter-heroku-test/venv/lib/python2.7/site-packages/psycopg2/__init__.py", line 164, in connect
    conn = _connect(dsn, connection_factory=connection_factory, async=async)
OperationalError: FATAL:  role "sportsfronter" does not exist

[24/Jun/2014 14:14:21] ERROR [django.request:212] Internal Server Error: /
Traceback (most recent call last):
  File "/Users/osmundmaheswaran/development/sportsfronter-heroku-test/venv/lib/python2.7/site-packages/django/core/handlers/base.py", line 103, in get_response
    resolver_match = resolver.resolve(request.path_info)
  File "/Users/osmundmaheswaran/development/sportsfronter-heroku-test/venv/lib/python2.7/site-packages/django/core/urlresolvers.py", line 319, in resolve
    for pattern in self.url_patterns:
  File "/Users/osmundmaheswaran/development/sportsfronter-heroku-test/venv/lib/python2.7/site-packages/django/core/urlresolvers.py", line 347, in url_patterns
    patterns = getattr(self.urlconf_module, "urlpatterns", self.urlconf_module)
  File "/Users/osmundmaheswaran/development/sportsfronter-heroku-test/venv/lib/python2.7/site-packages/django/core/urlresolvers.py", line 342, in urlconf_module
    self._urlconf_module = import_module(self.urlconf_name)
  File "/Users/osmundmaheswaran/development/sportsfronter-heroku-test/venv/lib/python2.7/site-packages/django/utils/importlib.py", line 35, in import_module
    __import__(name)
  File "/Users/osmundmaheswaran/development/sportsfronter-heroku-test/webapp/sportsfronter/urls.py", line 12, in <module>
    site = Site.objects.get(pk=1)
  File "/Users/osmundmaheswaran/development/sportsfronter-heroku-test/venv/lib/python2.7/site-packages/django/db/models/manager.py", line 143, in get
    return self.get_query_set().get(*args, **kwargs)
  File "/Users/osmundmaheswaran/development/sportsfronter-heroku-test/venv/lib/python2.7/site-packages/django/db/models/query.py", line 382, in get
    num = len(clone)
  File "/Users/osmundmaheswaran/development/sportsfronter-heroku-test/venv/lib/python2.7/site-packages/django/db/models/query.py", line 90, in __len__
    self._result_cache = list(self.iterator())
  File "/Users/osmundmaheswaran/development/sportsfronter-heroku-test/venv/lib/python2.7/site-packages/django/db/models/query.py", line 301, in iterator
    for row in compiler.results_iter():
  File "/Users/osmundmaheswaran/development/sportsfronter-heroku-test/venv/lib/python2.7/site-packages/django/db/models/sql/compiler.py", line 775, in results_iter
    for rows in self.execute_sql(MULTI):
  File "/Users/osmundmaheswaran/development/sportsfronter-heroku-test/venv/lib/python2.7/site-packages/django/db/models/sql/compiler.py", line 839, in execute_sql
    cursor = self.connection.cursor()
  File "/Users/osmundmaheswaran/development/sportsfronter-heroku-test/venv/lib/python2.7/site-packages/django/db/backends/__init__.py", line 324, in cursor
    cursor = self.make_debug_cursor(self._cursor())
  File "/Users/osmundmaheswaran/development/sportsfronter-heroku-test/venv/lib/python2.7/site-packages/django/db/backends/postgresql_psycopg2/base.py", line 182, in _cursor
    self.connection = Database.connect(**conn_params)
  File "/Users/osmundmaheswaran/development/sportsfronter-heroku-test/venv/lib/python2.7/site-packages/psycopg2/__init__.py", line 164, in connect
    conn = _connect(dsn, connection_factory=connection_factory, async=async)
OperationalError: FATAL:  role "sportsfronter" does not exist

[24/Jun/2014 14:14:21] ERROR [django.request:212] Internal Server Error: /favicon.ico
Traceback (most recent call last):
  File "/Users/osmundmaheswaran/development/sportsfronter-heroku-test/venv/lib/python2.7/site-packages/django/core/handlers/base.py", line 92, in get_response
    response = middleware_method(request)
  File "/Users/osmundmaheswaran/development/sportsfronter-heroku-test/venv/lib/python2.7/site-packages/django/middleware/common.py", line 69, in process_request
    if (not urlresolvers.is_valid_path(request.path_info, urlconf) and
  File "/Users/osmundmaheswaran/development/sportsfronter-heroku-test/venv/lib/python2.7/site-packages/django/core/urlresolvers.py", line 551, in is_valid_path
    resolve(path, urlconf)
  File "/Users/osmundmaheswaran/development/sportsfronter-heroku-test/venv/lib/python2.7/site-packages/django/core/urlresolvers.py", line 440, in resolve
    return get_resolver(urlconf).resolve(path)
  File "/Users/osmundmaheswaran/development/sportsfronter-heroku-test/venv/lib/python2.7/site-packages/django/core/urlresolvers.py", line 319, in resolve
    for pattern in self.url_patterns:
  File "/Users/osmundmaheswaran/development/sportsfronter-heroku-test/venv/lib/python2.7/site-packages/django/core/urlresolvers.py", line 347, in url_patterns
    patterns = getattr(self.urlconf_module, "urlpatterns", self.urlconf_module)
  File "/Users/osmundmaheswaran/development/sportsfronter-heroku-test/venv/lib/python2.7/site-packages/django/core/urlresolvers.py", line 342, in urlconf_module
    self._urlconf_module = import_module(self.urlconf_name)
  File "/Users/osmundmaheswaran/development/sportsfronter-heroku-test/venv/lib/python2.7/site-packages/django/utils/importlib.py", line 35, in import_module
    __import__(name)
  File "/Users/osmundmaheswaran/development/sportsfronter-heroku-test/webapp/sportsfronter/urls.py", line 12, in <module>
    site = Site.objects.get(pk=1)
  File "/Users/osmundmaheswaran/development/sportsfronter-heroku-test/venv/lib/python2.7/site-packages/django/db/models/manager.py", line 143, in get
    return self.get_query_set().get(*args, **kwargs)
  File "/Users/osmundmaheswaran/development/sportsfronter-heroku-test/venv/lib/python2.7/site-packages/django/db/models/query.py", line 382, in get
    num = len(clone)
  File "/Users/osmundmaheswaran/development/sportsfronter-heroku-test/venv/lib/python2.7/site-packages/django/db/models/query.py", line 90, in __len__
    self._result_cache = list(self.iterator())
  File "/Users/osmundmaheswaran/development/sportsfronter-heroku-test/venv/lib/python2.7/site-packages/django/db/models/query.py", line 301, in iterator
    for row in compiler.results_iter():
  File "/Users/osmundmaheswaran/development/sportsfronter-heroku-test/venv/lib/python2.7/site-packages/django/db/models/sql/compiler.py", line 775, in results_iter
    for rows in self.execute_sql(MULTI):
  File "/Users/osmundmaheswaran/development/sportsfronter-heroku-test/venv/lib/python2.7/site-packages/django/db/models/sql/compiler.py", line 839, in execute_sql
    cursor = self.connection.cursor()
  File "/Users/osmundmaheswaran/development/sportsfronter-heroku-test/venv/lib/python2.7/site-packages/django/db/backends/__init__.py", line 324, in cursor
    cursor = self.make_debug_cursor(self._cursor())
  File "/Users/osmundmaheswaran/development/sportsfronter-heroku-test/venv/lib/python2.7/site-packages/django/db/backends/postgresql_psycopg2/base.py", line 182, in _cursor
    self.connection = Database.connect(**conn_params)
  File "/Users/osmundmaheswaran/development/sportsfronter-heroku-test/venv/lib/python2.7/site-packages/psycopg2/__init__.py", line 164, in connect
    conn = _connect(dsn, connection_factory=connection_factory, async=async)
OperationalError: FATAL:  role "sportsfronter" does not exist

[24/Jun/2014 14:27:15] WARNING [django.request:146] Not Found: /favicon.ico
[24/Jun/2014 14:28:01] WARNING [django.request:146] Not Found: /favicon.ico
[25/Jun/2014 08:22:21] WARNING [django.request:146] Not Found: /static/webapp/js/angular-cookies.min.js.map
[25/Jun/2014 08:22:21] WARNING [django.request:146] Not Found: /static/webapp/js/angular.min.js.map
[25/Jun/2014 08:22:21] WARNING [django.request:146] Not Found: /static/webapp/js/jquery.min.map
[25/Jun/2014 08:22:21] WARNING [django.request:146] Not Found: /static/webapp/js/angular-touch.min.js.map
[25/Jun/2014 08:22:21] WARNING [django.request:146] Not Found: /static/webapp/js/angular-route.min.js.map
[25/Jun/2014 10:49:39] ERROR [django.request:212] Internal Server Error: /
Traceback (most recent call last):
  File "/Users/osmundmaheswaran/development/sportsfronter-heroku-test/venv/lib/python2.7/site-packages/django/core/handlers/base.py", line 103, in get_response
    resolver_match = resolver.resolve(request.path_info)
  File "/Users/osmundmaheswaran/development/sportsfronter-heroku-test/venv/lib/python2.7/site-packages/django/core/urlresolvers.py", line 319, in resolve
    for pattern in self.url_patterns:
  File "/Users/osmundmaheswaran/development/sportsfronter-heroku-test/venv/lib/python2.7/site-packages/django/core/urlresolvers.py", line 347, in url_patterns
    patterns = getattr(self.urlconf_module, "urlpatterns", self.urlconf_module)
  File "/Users/osmundmaheswaran/development/sportsfronter-heroku-test/venv/lib/python2.7/site-packages/django/core/urlresolvers.py", line 342, in urlconf_module
    self._urlconf_module = import_module(self.urlconf_name)
  File "/Users/osmundmaheswaran/development/sportsfronter-heroku-test/venv/lib/python2.7/site-packages/django/utils/importlib.py", line 35, in import_module
    __import__(name)
  File "/Users/osmundmaheswaran/development/sportsfronter-heroku-test/webapp/sportsfronter/urls.py", line 12, in <module>
    site = Site.objects.get(pk=1)
  File "/Users/osmundmaheswaran/development/sportsfronter-heroku-test/venv/lib/python2.7/site-packages/django/db/models/manager.py", line 143, in get
    return self.get_query_set().get(*args, **kwargs)
  File "/Users/osmundmaheswaran/development/sportsfronter-heroku-test/venv/lib/python2.7/site-packages/django/db/models/query.py", line 382, in get
    num = len(clone)
  File "/Users/osmundmaheswaran/development/sportsfronter-heroku-test/venv/lib/python2.7/site-packages/django/db/models/query.py", line 90, in __len__
    self._result_cache = list(self.iterator())
  File "/Users/osmundmaheswaran/development/sportsfronter-heroku-test/venv/lib/python2.7/site-packages/django/db/models/query.py", line 301, in iterator
    for row in compiler.results_iter():
  File "/Users/osmundmaheswaran/development/sportsfronter-heroku-test/venv/lib/python2.7/site-packages/django/db/models/sql/compiler.py", line 775, in results_iter
    for rows in self.execute_sql(MULTI):
  File "/Users/osmundmaheswaran/development/sportsfronter-heroku-test/venv/lib/python2.7/site-packages/django/db/models/sql/compiler.py", line 839, in execute_sql
    cursor = self.connection.cursor()
  File "/Users/osmundmaheswaran/development/sportsfronter-heroku-test/venv/lib/python2.7/site-packages/django/db/backends/__init__.py", line 324, in cursor
    cursor = self.make_debug_cursor(self._cursor())
  File "/Users/osmundmaheswaran/development/sportsfronter-heroku-test/venv/lib/python2.7/site-packages/django/db/backends/postgresql_psycopg2/base.py", line 182, in _cursor
    self.connection = Database.connect(**conn_params)
  File "/Users/osmundmaheswaran/development/sportsfronter-heroku-test/venv/lib/python2.7/site-packages/psycopg2/__init__.py", line 164, in connect
    conn = _connect(dsn, connection_factory=connection_factory, async=async)
OperationalError: could not connect to server: Connection refused
	Is the server running on host "localhost" (::1) and accepting
	TCP/IP connections on port 5432?
could not connect to server: Connection refused
	Is the server running on host "localhost" (fe80::1) and accepting
	TCP/IP connections on port 5432?
could not connect to server: Connection refused
	Is the server running on host "localhost" (127.0.0.1) and accepting
	TCP/IP connections on port 5432?

[25/Jun/2014 10:49:39] ERROR [django.request:212] Internal Server Error: /favicon.ico
Traceback (most recent call last):
  File "/Users/osmundmaheswaran/development/sportsfronter-heroku-test/venv/lib/python2.7/site-packages/django/core/handlers/base.py", line 92, in get_response
    response = middleware_method(request)
  File "/Users/osmundmaheswaran/development/sportsfronter-heroku-test/venv/lib/python2.7/site-packages/django/middleware/common.py", line 69, in process_request
    if (not urlresolvers.is_valid_path(request.path_info, urlconf) and
  File "/Users/osmundmaheswaran/development/sportsfronter-heroku-test/venv/lib/python2.7/site-packages/django/core/urlresolvers.py", line 551, in is_valid_path
    resolve(path, urlconf)
  File "/Users/osmundmaheswaran/development/sportsfronter-heroku-test/venv/lib/python2.7/site-packages/django/core/urlresolvers.py", line 440, in resolve
    return get_resolver(urlconf).resolve(path)
  File "/Users/osmundmaheswaran/development/sportsfronter-heroku-test/venv/lib/python2.7/site-packages/django/core/urlresolvers.py", line 319, in resolve
    for pattern in self.url_patterns:
  File "/Users/osmundmaheswaran/development/sportsfronter-heroku-test/venv/lib/python2.7/site-packages/django/core/urlresolvers.py", line 347, in url_patterns
    patterns = getattr(self.urlconf_module, "urlpatterns", self.urlconf_module)
  File "/Users/osmundmaheswaran/development/sportsfronter-heroku-test/venv/lib/python2.7/site-packages/django/core/urlresolvers.py", line 342, in urlconf_module
    self._urlconf_module = import_module(self.urlconf_name)
  File "/Users/osmundmaheswaran/development/sportsfronter-heroku-test/venv/lib/python2.7/site-packages/django/utils/importlib.py", line 35, in import_module
    __import__(name)
  File "/Users/osmundmaheswaran/development/sportsfronter-heroku-test/webapp/sportsfronter/urls.py", line 12, in <module>
    site = Site.objects.get(pk=1)
  File "/Users/osmundmaheswaran/development/sportsfronter-heroku-test/venv/lib/python2.7/site-packages/django/db/models/manager.py", line 143, in get
    return self.get_query_set().get(*args, **kwargs)
  File "/Users/osmundmaheswaran/development/sportsfronter-heroku-test/venv/lib/python2.7/site-packages/django/db/models/query.py", line 382, in get
    num = len(clone)
  File "/Users/osmundmaheswaran/development/sportsfronter-heroku-test/venv/lib/python2.7/site-packages/django/db/models/query.py", line 90, in __len__
    self._result_cache = list(self.iterator())
  File "/Users/osmundmaheswaran/development/sportsfronter-heroku-test/venv/lib/python2.7/site-packages/django/db/models/query.py", line 301, in iterator
    for row in compiler.results_iter():
  File "/Users/osmundmaheswaran/development/sportsfronter-heroku-test/venv/lib/python2.7/site-packages/django/db/models/sql/compiler.py", line 775, in results_iter
    for rows in self.execute_sql(MULTI):
  File "/Users/osmundmaheswaran/development/sportsfronter-heroku-test/venv/lib/python2.7/site-packages/django/db/models/sql/compiler.py", line 839, in execute_sql
    cursor = self.connection.cursor()
  File "/Users/osmundmaheswaran/development/sportsfronter-heroku-test/venv/lib/python2.7/site-packages/django/db/backends/__init__.py", line 324, in cursor
    cursor = self.make_debug_cursor(self._cursor())
  File "/Users/osmundmaheswaran/development/sportsfronter-heroku-test/venv/lib/python2.7/site-packages/django/db/backends/postgresql_psycopg2/base.py", line 182, in _cursor
    self.connection = Database.connect(**conn_params)
  File "/Users/osmundmaheswaran/development/sportsfronter-heroku-test/venv/lib/python2.7/site-packages/psycopg2/__init__.py", line 164, in connect
    conn = _connect(dsn, connection_factory=connection_factory, async=async)
OperationalError: could not connect to server: Connection refused
	Is the server running on host "localhost" (::1) and accepting
	TCP/IP connections on port 5432?
could not connect to server: Connection refused
	Is the server running on host "localhost" (fe80::1) and accepting
	TCP/IP connections on port 5432?
could not connect to server: Connection refused
	Is the server running on host "localhost" (127.0.0.1) and accepting
	TCP/IP connections on port 5432?

[25/Jun/2014 10:56:02] WARNING [django.request:146] Not Found: /favicon.ico
[25/Jun/2014 10:56:05] WARNING [django.request:146] Not Found: /static/webapp/js/angular-route.min.js.map
[25/Jun/2014 10:56:05] WARNING [django.request:146] Not Found: /static/webapp/js/angular-cookies.min.js.map
[25/Jun/2014 10:56:05] WARNING [django.request:146] Not Found: /static/webapp/js/jquery.min.map
[25/Jun/2014 10:56:05] WARNING [django.request:146] Not Found: /static/webapp/js/angular-touch.min.js.map
[25/Jun/2014 10:56:05] WARNING [django.request:146] Not Found: /static/webapp/js/angular.min.js.map
[25/Jun/2014 10:56:24] INFO [sportsfronter.auth.views:251] data: {"username": "gunicorn@example.com", "firstName": "Gunni", "lastName": "Corn", "userRoles": {"player": false, "manager": false, "guardian": false}, "password": "random", "newUser": true}
[25/Jun/2014 10:56:24] ERROR [django.request:212] Internal Server Error: /auth/register
Traceback (most recent call last):
  File "/Users/osmundmaheswaran/development/sportsfronter-heroku-test/venv/lib/python2.7/site-packages/django/core/handlers/base.py", line 115, in get_response
    response = callback(request, *callback_args, **callback_kwargs)
  File "/Users/osmundmaheswaran/development/sportsfronter-heroku-test/venv/lib/python2.7/site-packages/django/views/decorators/csrf.py", line 77, in wrapped_view
    return view_func(*args, **kwargs)
  File "/Users/osmundmaheswaran/development/sportsfronter-heroku-test/webapp/auth/views.py", line 295, in register
    Token.objects.create(user=person).save()
  File "/Users/osmundmaheswaran/development/sportsfronter-heroku-test/venv/lib/python2.7/site-packages/django/db/models/manager.py", line 149, in create
    return self.get_query_set().create(**kwargs)
  File "/Users/osmundmaheswaran/development/sportsfronter-heroku-test/venv/lib/python2.7/site-packages/django/db/models/query.py", line 402, in create
    obj.save(force_insert=True, using=self.db)
  File "/Users/osmundmaheswaran/development/sportsfronter-heroku-test/venv/lib/python2.7/site-packages/rest_framework/authtoken/models.py", line 28, in save
    return super(Token, self).save(*args, **kwargs)
  File "/Users/osmundmaheswaran/development/sportsfronter-heroku-test/venv/lib/python2.7/site-packages/django/db/models/base.py", line 546, in save
    force_update=force_update, update_fields=update_fields)
  File "/Users/osmundmaheswaran/development/sportsfronter-heroku-test/venv/lib/python2.7/site-packages/django/db/models/base.py", line 650, in save_base
    result = manager._insert([self], fields=fields, return_id=update_pk, using=using, raw=raw)
  File "/Users/osmundmaheswaran/development/sportsfronter-heroku-test/venv/lib/python2.7/site-packages/django/db/models/manager.py", line 215, in _insert
    return insert_query(self.model, objs, fields, **kwargs)
  File "/Users/osmundmaheswaran/development/sportsfronter-heroku-test/venv/lib/python2.7/site-packages/django/db/models/query.py", line 1661, in insert_query
    return query.get_compiler(using=using).execute_sql(return_id)
  File "/Users/osmundmaheswaran/development/sportsfronter-heroku-test/venv/lib/python2.7/site-packages/django/db/models/sql/compiler.py", line 937, in execute_sql
    cursor.execute(sql, params)
  File "/Users/osmundmaheswaran/development/sportsfronter-heroku-test/venv/lib/python2.7/site-packages/django/db/backends/util.py", line 41, in execute
    return self.cursor.execute(sql, params)
  File "/Users/osmundmaheswaran/development/sportsfronter-heroku-test/venv/lib/python2.7/site-packages/django/db/backends/postgresql_psycopg2/base.py", line 58, in execute
    six.reraise(utils.DatabaseError, utils.DatabaseError(*tuple(e.args)), sys.exc_info()[2])
  File "/Users/osmundmaheswaran/development/sportsfronter-heroku-test/venv/lib/python2.7/site-packages/django/db/backends/postgresql_psycopg2/base.py", line 54, in execute
    return self.cursor.execute(query, args)
DatabaseError: relation "authtoken_token" does not exist
LINE 1: INSERT INTO "authtoken_token" ("key", "user_id", "created") ...
                    ^

[25/Jun/2014 10:57:32] INFO [sportsfronter.auth.views:251] data: {"username": "gunicorn@example.com", "firstName": "Gunni", "lastName": "Corn", "userRoles": {"player": false, "manager": false, "guardian": false}, "password": "random", "newUser": true}
[25/Jun/2014 10:57:32] INFO [sportsfronter.auth.views:192] data: {"username": "gunicorn@example.com", "password": "random"}
[25/Jun/2014 10:57:32] ERROR [django.request:212] Internal Server Error: /auth/login
Traceback (most recent call last):
  File "/Users/osmundmaheswaran/development/sportsfronter-heroku-test/venv/lib/python2.7/site-packages/django/core/handlers/base.py", line 115, in get_response
    response = callback(request, *callback_args, **callback_kwargs)
  File "/Users/osmundmaheswaran/development/sportsfronter-heroku-test/venv/lib/python2.7/site-packages/django/views/decorators/csrf.py", line 77, in wrapped_view
    return view_func(*args, **kwargs)
  File "/Users/osmundmaheswaran/development/sportsfronter-heroku-test/webapp/auth/views.py", line 206, in _login
    token = Token.objects.create(user=user).pk
  File "/Users/osmundmaheswaran/development/sportsfronter-heroku-test/venv/lib/python2.7/site-packages/django/db/models/manager.py", line 149, in create
    return self.get_query_set().create(**kwargs)
  File "/Users/osmundmaheswaran/development/sportsfronter-heroku-test/venv/lib/python2.7/site-packages/django/db/models/query.py", line 402, in create
    obj.save(force_insert=True, using=self.db)
  File "/Users/osmundmaheswaran/development/sportsfronter-heroku-test/venv/lib/python2.7/site-packages/rest_framework/authtoken/models.py", line 28, in save
    return super(Token, self).save(*args, **kwargs)
  File "/Users/osmundmaheswaran/development/sportsfronter-heroku-test/venv/lib/python2.7/site-packages/django/db/models/base.py", line 546, in save
    force_update=force_update, update_fields=update_fields)
  File "/Users/osmundmaheswaran/development/sportsfronter-heroku-test/venv/lib/python2.7/site-packages/django/db/models/base.py", line 650, in save_base
    result = manager._insert([self], fields=fields, return_id=update_pk, using=using, raw=raw)
  File "/Users/osmundmaheswaran/development/sportsfronter-heroku-test/venv/lib/python2.7/site-packages/django/db/models/manager.py", line 215, in _insert
    return insert_query(self.model, objs, fields, **kwargs)
  File "/Users/osmundmaheswaran/development/sportsfronter-heroku-test/venv/lib/python2.7/site-packages/django/db/models/query.py", line 1661, in insert_query
    return query.get_compiler(using=using).execute_sql(return_id)
  File "/Users/osmundmaheswaran/development/sportsfronter-heroku-test/venv/lib/python2.7/site-packages/django/db/models/sql/compiler.py", line 937, in execute_sql
    cursor.execute(sql, params)
  File "/Users/osmundmaheswaran/development/sportsfronter-heroku-test/venv/lib/python2.7/site-packages/django/db/backends/util.py", line 41, in execute
    return self.cursor.execute(sql, params)
  File "/Users/osmundmaheswaran/development/sportsfronter-heroku-test/venv/lib/python2.7/site-packages/django/db/backends/postgresql_psycopg2/base.py", line 58, in execute
    six.reraise(utils.DatabaseError, utils.DatabaseError(*tuple(e.args)), sys.exc_info()[2])
  File "/Users/osmundmaheswaran/development/sportsfronter-heroku-test/venv/lib/python2.7/site-packages/django/db/backends/postgresql_psycopg2/base.py", line 54, in execute
    return self.cursor.execute(query, args)
DatabaseError: current transaction is aborted, commands ignored until end of transaction block

[25/Jun/2014 10:57:41] WARNING [django.request:146] Not Found: /static/webapp/js/angular.min.js.map
[25/Jun/2014 10:57:41] WARNING [django.request:146] Not Found: /static/webapp/js/jquery.min.map
[25/Jun/2014 10:57:41] WARNING [django.request:146] Not Found: /static/webapp/js/angular-cookies.min.js.map
[25/Jun/2014 10:57:41] WARNING [django.request:146] Not Found: /static/webapp/js/angular-route.min.js.map
[25/Jun/2014 10:57:41] WARNING [django.request:146] Not Found: /static/webapp/js/angular-touch.min.js.map
[26/Jun/2014 08:24:16] WARNING [django.request:146] Not Found: /static/webapp/js/angular.min.js.map
[26/Jun/2014 08:24:16] WARNING [django.request:146] Not Found: /static/webapp/js/jquery.min.map
[26/Jun/2014 08:24:16] WARNING [django.request:146] Not Found: /static/webapp/js/angular-cookies.min.js.map
[26/Jun/2014 08:24:16] WARNING [django.request:146] Not Found: /static/webapp/js/angular-route.min.js.map
[26/Jun/2014 08:24:16] WARNING [django.request:146] Not Found: /static/webapp/js/angular-touch.min.js.map
[26/Jun/2014 08:24:16] WARNING [django.request:146] Not Found: /favicon.ico
[26/Jun/2014 08:24:26] INFO [sportsfronter.auth.views:192] data: {"username": "gunicorn@example.com", "password": "random"}
[26/Jun/2014 08:24:26] ERROR [django.request:212] Internal Server Error: /auth/login
Traceback (most recent call last):
  File "/Users/osmundmaheswaran/development/sportsfronter-heroku-test/venv/lib/python2.7/site-packages/django/core/handlers/base.py", line 115, in get_response
    response = callback(request, *callback_args, **callback_kwargs)
  File "/Users/osmundmaheswaran/development/sportsfronter-heroku-test/venv/lib/python2.7/site-packages/django/views/decorators/csrf.py", line 77, in wrapped_view
    return view_func(*args, **kwargs)
  File "/Users/osmundmaheswaran/development/sportsfronter-heroku-test/webapp/auth/views.py", line 206, in _login
    token = Token.objects.create(user=user).pk
  File "/Users/osmundmaheswaran/development/sportsfronter-heroku-test/venv/lib/python2.7/site-packages/django/db/models/manager.py", line 149, in create
    return self.get_query_set().create(**kwargs)
  File "/Users/osmundmaheswaran/development/sportsfronter-heroku-test/venv/lib/python2.7/site-packages/django/db/models/query.py", line 402, in create
    obj.save(force_insert=True, using=self.db)
  File "/Users/osmundmaheswaran/development/sportsfronter-heroku-test/venv/lib/python2.7/site-packages/rest_framework/authtoken/models.py", line 28, in save
    return super(Token, self).save(*args, **kwargs)
  File "/Users/osmundmaheswaran/development/sportsfronter-heroku-test/venv/lib/python2.7/site-packages/django/db/models/base.py", line 546, in save
    force_update=force_update, update_fields=update_fields)
  File "/Users/osmundmaheswaran/development/sportsfronter-heroku-test/venv/lib/python2.7/site-packages/django/db/models/base.py", line 650, in save_base
    result = manager._insert([self], fields=fields, return_id=update_pk, using=using, raw=raw)
  File "/Users/osmundmaheswaran/development/sportsfronter-heroku-test/venv/lib/python2.7/site-packages/django/db/models/manager.py", line 215, in _insert
    return insert_query(self.model, objs, fields, **kwargs)
  File "/Users/osmundmaheswaran/development/sportsfronter-heroku-test/venv/lib/python2.7/site-packages/django/db/models/query.py", line 1661, in insert_query
    return query.get_compiler(using=using).execute_sql(return_id)
  File "/Users/osmundmaheswaran/development/sportsfronter-heroku-test/venv/lib/python2.7/site-packages/django/db/models/sql/compiler.py", line 937, in execute_sql
    cursor.execute(sql, params)
  File "/Users/osmundmaheswaran/development/sportsfronter-heroku-test/venv/lib/python2.7/site-packages/django/db/backends/util.py", line 41, in execute
    return self.cursor.execute(sql, params)
  File "/Users/osmundmaheswaran/development/sportsfronter-heroku-test/venv/lib/python2.7/site-packages/django/db/backends/postgresql_psycopg2/base.py", line 58, in execute
    six.reraise(utils.DatabaseError, utils.DatabaseError(*tuple(e.args)), sys.exc_info()[2])
  File "/Users/osmundmaheswaran/development/sportsfronter-heroku-test/venv/lib/python2.7/site-packages/django/db/backends/postgresql_psycopg2/base.py", line 54, in execute
    return self.cursor.execute(query, args)
DatabaseError: current transaction is aborted, commands ignored until end of transaction block

[26/Jun/2014 08:26:06] INFO [sportsfronter.auth.views:192] data: {"username": "gunicorn@example.com", "password": "random"}
[26/Jun/2014 08:26:06] ERROR [django.request:212] Internal Server Error: /auth/login
Traceback (most recent call last):
  File "/Users/osmundmaheswaran/development/sportsfronter-heroku-test/venv/lib/python2.7/site-packages/django/core/handlers/base.py", line 115, in get_response
    response = callback(request, *callback_args, **callback_kwargs)
  File "/Users/osmundmaheswaran/development/sportsfronter-heroku-test/venv/lib/python2.7/site-packages/django/views/decorators/csrf.py", line 77, in wrapped_view
    return view_func(*args, **kwargs)
  File "/Users/osmundmaheswaran/development/sportsfronter-heroku-test/webapp/auth/views.py", line 206, in _login
    token = Token.objects.create(user=user).pk
  File "/Users/osmundmaheswaran/development/sportsfronter-heroku-test/venv/lib/python2.7/site-packages/django/db/models/manager.py", line 149, in create
    return self.get_query_set().create(**kwargs)
  File "/Users/osmundmaheswaran/development/sportsfronter-heroku-test/venv/lib/python2.7/site-packages/django/db/models/query.py", line 402, in create
    obj.save(force_insert=True, using=self.db)
  File "/Users/osmundmaheswaran/development/sportsfronter-heroku-test/venv/lib/python2.7/site-packages/rest_framework/authtoken/models.py", line 28, in save
    return super(Token, self).save(*args, **kwargs)
  File "/Users/osmundmaheswaran/development/sportsfronter-heroku-test/venv/lib/python2.7/site-packages/django/db/models/base.py", line 546, in save
    force_update=force_update, update_fields=update_fields)
  File "/Users/osmundmaheswaran/development/sportsfronter-heroku-test/venv/lib/python2.7/site-packages/django/db/models/base.py", line 650, in save_base
    result = manager._insert([self], fields=fields, return_id=update_pk, using=using, raw=raw)
  File "/Users/osmundmaheswaran/development/sportsfronter-heroku-test/venv/lib/python2.7/site-packages/django/db/models/manager.py", line 215, in _insert
    return insert_query(self.model, objs, fields, **kwargs)
  File "/Users/osmundmaheswaran/development/sportsfronter-heroku-test/venv/lib/python2.7/site-packages/django/db/models/query.py", line 1661, in insert_query
    return query.get_compiler(using=using).execute_sql(return_id)
  File "/Users/osmundmaheswaran/development/sportsfronter-heroku-test/venv/lib/python2.7/site-packages/django/db/models/sql/compiler.py", line 937, in execute_sql
    cursor.execute(sql, params)
  File "/Users/osmundmaheswaran/development/sportsfronter-heroku-test/venv/lib/python2.7/site-packages/django/db/backends/util.py", line 41, in execute
    return self.cursor.execute(sql, params)
  File "/Users/osmundmaheswaran/development/sportsfronter-heroku-test/venv/lib/python2.7/site-packages/django/db/backends/postgresql_psycopg2/base.py", line 58, in execute
    six.reraise(utils.DatabaseError, utils.DatabaseError(*tuple(e.args)), sys.exc_info()[2])
  File "/Users/osmundmaheswaran/development/sportsfronter-heroku-test/venv/lib/python2.7/site-packages/django/db/backends/postgresql_psycopg2/base.py", line 54, in execute
    return self.cursor.execute(query, args)
DatabaseError: current transaction is aborted, commands ignored until end of transaction block

[26/Jun/2014 08:26:18] WARNING [django.request:146] Not Found: /static/webapp/js/angular.min.js.map
[26/Jun/2014 08:26:18] WARNING [django.request:146] Not Found: /static/webapp/js/angular-cookies.min.js.map
[26/Jun/2014 08:26:18] WARNING [django.request:146] Not Found: /static/webapp/js/angular-route.min.js.map
[26/Jun/2014 08:26:18] WARNING [django.request:146] Not Found: /static/webapp/js/jquery.min.map
[26/Jun/2014 08:26:18] WARNING [django.request:146] Not Found: /static/webapp/js/angular-touch.min.js.map
[26/Jun/2014 08:26:34] INFO [sportsfronter.auth.views:192] data: {"username": "gunicorn@example.com", "password": "random"}
[26/Jun/2014 08:26:34] ERROR [django.request:212] Internal Server Error: /auth/login
Traceback (most recent call last):
  File "/Users/osmundmaheswaran/development/sportsfronter-heroku-test/venv/lib/python2.7/site-packages/django/core/handlers/base.py", line 115, in get_response
    response = callback(request, *callback_args, **callback_kwargs)
  File "/Users/osmundmaheswaran/development/sportsfronter-heroku-test/venv/lib/python2.7/site-packages/django/views/decorators/csrf.py", line 77, in wrapped_view
    return view_func(*args, **kwargs)
  File "/Users/osmundmaheswaran/development/sportsfronter-heroku-test/webapp/auth/views.py", line 206, in _login
    token = Token.objects.create(user=user).pk
  File "/Users/osmundmaheswaran/development/sportsfronter-heroku-test/venv/lib/python2.7/site-packages/django/db/models/manager.py", line 149, in create
    return self.get_query_set().create(**kwargs)
  File "/Users/osmundmaheswaran/development/sportsfronter-heroku-test/venv/lib/python2.7/site-packages/django/db/models/query.py", line 402, in create
    obj.save(force_insert=True, using=self.db)
  File "/Users/osmundmaheswaran/development/sportsfronter-heroku-test/venv/lib/python2.7/site-packages/rest_framework/authtoken/models.py", line 28, in save
    return super(Token, self).save(*args, **kwargs)
  File "/Users/osmundmaheswaran/development/sportsfronter-heroku-test/venv/lib/python2.7/site-packages/django/db/models/base.py", line 546, in save
    force_update=force_update, update_fields=update_fields)
  File "/Users/osmundmaheswaran/development/sportsfronter-heroku-test/venv/lib/python2.7/site-packages/django/db/models/base.py", line 650, in save_base
    result = manager._insert([self], fields=fields, return_id=update_pk, using=using, raw=raw)
  File "/Users/osmundmaheswaran/development/sportsfronter-heroku-test/venv/lib/python2.7/site-packages/django/db/models/manager.py", line 215, in _insert
    return insert_query(self.model, objs, fields, **kwargs)
  File "/Users/osmundmaheswaran/development/sportsfronter-heroku-test/venv/lib/python2.7/site-packages/django/db/models/query.py", line 1661, in insert_query
    return query.get_compiler(using=using).execute_sql(return_id)
  File "/Users/osmundmaheswaran/development/sportsfronter-heroku-test/venv/lib/python2.7/site-packages/django/db/models/sql/compiler.py", line 937, in execute_sql
    cursor.execute(sql, params)
  File "/Users/osmundmaheswaran/development/sportsfronter-heroku-test/venv/lib/python2.7/site-packages/django/db/backends/util.py", line 41, in execute
    return self.cursor.execute(sql, params)
  File "/Users/osmundmaheswaran/development/sportsfronter-heroku-test/venv/lib/python2.7/site-packages/django/db/backends/postgresql_psycopg2/base.py", line 58, in execute
    six.reraise(utils.DatabaseError, utils.DatabaseError(*tuple(e.args)), sys.exc_info()[2])
  File "/Users/osmundmaheswaran/development/sportsfronter-heroku-test/venv/lib/python2.7/site-packages/django/db/backends/postgresql_psycopg2/base.py", line 54, in execute
    return self.cursor.execute(query, args)
DatabaseError: current transaction is aborted, commands ignored until end of transaction block

[26/Jun/2014 08:28:20] INFO [sportsfronter.auth.views:192] data: {"username": "gunicorn@example.com", "password": "random"}
[26/Jun/2014 08:28:20] ERROR [django.request:212] Internal Server Error: /auth/login
Traceback (most recent call last):
  File "/Users/osmundmaheswaran/development/sportsfronter-heroku-test/venv/lib/python2.7/site-packages/django/core/handlers/base.py", line 115, in get_response
    response = callback(request, *callback_args, **callback_kwargs)
  File "/Users/osmundmaheswaran/development/sportsfronter-heroku-test/venv/lib/python2.7/site-packages/django/views/decorators/csrf.py", line 77, in wrapped_view
    return view_func(*args, **kwargs)
  File "/Users/osmundmaheswaran/development/sportsfronter-heroku-test/webapp/auth/views.py", line 206, in _login
    token = Token.objects.create(user=user).pk
  File "/Users/osmundmaheswaran/development/sportsfronter-heroku-test/venv/lib/python2.7/site-packages/django/db/models/manager.py", line 149, in create
    return self.get_query_set().create(**kwargs)
  File "/Users/osmundmaheswaran/development/sportsfronter-heroku-test/venv/lib/python2.7/site-packages/django/db/models/query.py", line 402, in create
    obj.save(force_insert=True, using=self.db)
  File "/Users/osmundmaheswaran/development/sportsfronter-heroku-test/venv/lib/python2.7/site-packages/rest_framework/authtoken/models.py", line 28, in save
    return super(Token, self).save(*args, **kwargs)
  File "/Users/osmundmaheswaran/development/sportsfronter-heroku-test/venv/lib/python2.7/site-packages/django/db/models/base.py", line 546, in save
    force_update=force_update, update_fields=update_fields)
  File "/Users/osmundmaheswaran/development/sportsfronter-heroku-test/venv/lib/python2.7/site-packages/django/db/models/base.py", line 650, in save_base
    result = manager._insert([self], fields=fields, return_id=update_pk, using=using, raw=raw)
  File "/Users/osmundmaheswaran/development/sportsfronter-heroku-test/venv/lib/python2.7/site-packages/django/db/models/manager.py", line 215, in _insert
    return insert_query(self.model, objs, fields, **kwargs)
  File "/Users/osmundmaheswaran/development/sportsfronter-heroku-test/venv/lib/python2.7/site-packages/django/db/models/query.py", line 1661, in insert_query
    return query.get_compiler(using=using).execute_sql(return_id)
  File "/Users/osmundmaheswaran/development/sportsfronter-heroku-test/venv/lib/python2.7/site-packages/django/db/models/sql/compiler.py", line 937, in execute_sql
    cursor.execute(sql, params)
  File "/Users/osmundmaheswaran/development/sportsfronter-heroku-test/venv/lib/python2.7/site-packages/django/db/backends/util.py", line 41, in execute
    return self.cursor.execute(sql, params)
  File "/Users/osmundmaheswaran/development/sportsfronter-heroku-test/venv/lib/python2.7/site-packages/django/db/backends/postgresql_psycopg2/base.py", line 58, in execute
    six.reraise(utils.DatabaseError, utils.DatabaseError(*tuple(e.args)), sys.exc_info()[2])
  File "/Users/osmundmaheswaran/development/sportsfronter-heroku-test/venv/lib/python2.7/site-packages/django/db/backends/postgresql_psycopg2/base.py", line 54, in execute
    return self.cursor.execute(query, args)
DatabaseError: current transaction is aborted, commands ignored until end of transaction block

[26/Jun/2014 08:29:54] WARNING [django.request:146] Not Found: /static/webapp/js/angular.min.js.map
[26/Jun/2014 08:29:54] WARNING [django.request:146] Not Found: /static/webapp/js/jquery.min.map
[26/Jun/2014 08:29:54] WARNING [django.request:146] Not Found: /static/webapp/js/angular-cookies.min.js.map
[26/Jun/2014 08:29:54] WARNING [django.request:146] Not Found: /static/webapp/js/angular-route.min.js.map
[26/Jun/2014 08:29:54] WARNING [django.request:146] Not Found: /static/webapp/js/angular-touch.min.js.map
[26/Jun/2014 08:29:54] WARNING [django.request:146] Not Found: /favicon.ico
[26/Jun/2014 08:30:05] INFO [sportsfronter.auth.views:192] data: {"username": "gunicorn@example.com", "password": "random"}
